Failure # 1 (occurred at 2024-05-23_10-50-46)
Traceback (most recent call last):
  File "C:\Users\onebean5\anaconda3\envs\marllib\lib\site-packages\ray\tune\trial_runner.py", line 890, in _process_trial
    results = self.trial_executor.fetch_result(trial)
  File "C:\Users\onebean5\anaconda3\envs\marllib\lib\site-packages\ray\tune\ray_trial_executor.py", line 788, in fetch_result
    result = ray.get(trial_future[0], timeout=DEFAULT_GET_TIMEOUT)
  File "C:\Users\onebean5\anaconda3\envs\marllib\lib\site-packages\ray\_private\client_mode_hook.py", line 105, in wrapper
    return func(*args, **kwargs)
  File "C:\Users\onebean5\anaconda3\envs\marllib\lib\site-packages\ray\worker.py", line 1625, in get
    raise value.as_instanceof_cause()
ray.exceptions.RayTaskError(AttributeError): [36mray::IA2CTrainer.train()[39m (pid=30204, ip=127.0.0.1, repr=IA2CTrainer)
  File "python\ray\_raylet.pyx", line 565, in ray._raylet.execute_task
  File "python\ray\_raylet.pyx", line 569, in ray._raylet.execute_task
  File "python\ray\_raylet.pyx", line 519, in ray._raylet.execute_task.function_executor
  File "C:\Users\onebean5\anaconda3\envs\marllib\lib\site-packages\ray\_private\function_manager.py", line 576, in actor_method_executor
    return method(__ray_actor, *args, **kwargs)
  File "C:\Users\onebean5\anaconda3\envs\marllib\lib\site-packages\ray\util\tracing\tracing_helper.py", line 451, in _resume_span
    return method(self, *_args, **_kwargs)
  File "C:\Users\onebean5\anaconda3\envs\marllib\lib\site-packages\ray\rllib\agents\trainer.py", line 679, in train
    raise e
  File "C:\Users\onebean5\anaconda3\envs\marllib\lib\site-packages\ray\rllib\agents\trainer.py", line 668, in train
    result = Trainable.train(self)
  File "C:\Users\onebean5\anaconda3\envs\marllib\lib\site-packages\ray\tune\trainable.py", line 283, in train
    result = self.step()
  File "C:\Users\onebean5\anaconda3\envs\marllib\lib\site-packages\ray\util\tracing\tracing_helper.py", line 451, in _resume_span
    return method(self, *_args, **_kwargs)
  File "C:\Users\onebean5\anaconda3\envs\marllib\lib\site-packages\ray\rllib\agents\trainer_template.py", line 206, in step
    step_results = next(self.train_exec_impl)
  File "C:\Users\onebean5\anaconda3\envs\marllib\lib\site-packages\ray\util\iter.py", line 756, in __next__
    return next(self.built_iterator)
  File "C:\Users\onebean5\anaconda3\envs\marllib\lib\site-packages\ray\util\iter.py", line 783, in apply_foreach
    for item in it:
  File "C:\Users\onebean5\anaconda3\envs\marllib\lib\site-packages\ray\util\iter.py", line 843, in apply_filter
    for item in it:
  File "C:\Users\onebean5\anaconda3\envs\marllib\lib\site-packages\ray\util\iter.py", line 843, in apply_filter
    for item in it:
  File "C:\Users\onebean5\anaconda3\envs\marllib\lib\site-packages\ray\util\iter.py", line 783, in apply_foreach
    for item in it:
  File "C:\Users\onebean5\anaconda3\envs\marllib\lib\site-packages\ray\util\iter.py", line 876, in apply_flatten
    for item in it:
  File "C:\Users\onebean5\anaconda3\envs\marllib\lib\site-packages\ray\util\iter.py", line 783, in apply_foreach
    for item in it:
  File "C:\Users\onebean5\anaconda3\envs\marllib\lib\site-packages\ray\util\iter.py", line 783, in apply_foreach
    for item in it:
  File "C:\Users\onebean5\anaconda3\envs\marllib\lib\site-packages\ray\util\iter.py", line 783, in apply_foreach
    for item in it:
  File "C:\Users\onebean5\anaconda3\envs\marllib\lib\site-packages\ray\util\iter.py", line 471, in base_iterator
    yield ray.get(futures, timeout=timeout)
  File "C:\Users\onebean5\anaconda3\envs\marllib\lib\site-packages\ray\_private\client_mode_hook.py", line 105, in wrapper
    return func(*args, **kwargs)
  File "C:\Users\onebean5\anaconda3\envs\marllib\lib\site-packages\ray\worker.py", line 1625, in get
    raise value.as_instanceof_cause()
ray.exceptions.RayTaskError(AttributeError): [36mray::RolloutWorker.par_iter_next()[39m (pid=30204, ip=127.0.0.1, repr=<ray.rllib.evaluation.rollout_worker.modify_class.<locals>.Class object at 0x0000023A5A635580>)
  File "python\ray\_raylet.pyx", line 565, in ray._raylet.execute_task
  File "python\ray\_raylet.pyx", line 569, in ray._raylet.execute_task
  File "python\ray\_raylet.pyx", line 519, in ray._raylet.execute_task.function_executor
  File "C:\Users\onebean5\anaconda3\envs\marllib\lib\site-packages\ray\_private\function_manager.py", line 576, in actor_method_executor
    return method(__ray_actor, *args, **kwargs)
  File "C:\Users\onebean5\anaconda3\envs\marllib\lib\site-packages\ray\util\tracing\tracing_helper.py", line 451, in _resume_span
    return method(self, *_args, **_kwargs)
  File "C:\Users\onebean5\anaconda3\envs\marllib\lib\site-packages\ray\util\iter.py", line 1151, in par_iter_next
    return next(self.local_it)
  File "C:\Users\onebean5\anaconda3\envs\marllib\lib\site-packages\ray\rllib\evaluation\rollout_worker.py", line 378, in gen_rollouts
    yield self.sample()
  File "C:\Users\onebean5\anaconda3\envs\marllib\lib\site-packages\ray\util\tracing\tracing_helper.py", line 451, in _resume_span
    return method(self, *_args, **_kwargs)
  File "C:\Users\onebean5\anaconda3\envs\marllib\lib\site-packages\ray\rllib\evaluation\rollout_worker.py", line 753, in sample
    batches = [self.input_reader.next()]
  File "C:\Users\onebean5\anaconda3\envs\marllib\lib\site-packages\ray\rllib\evaluation\sampler.py", line 103, in next
    batches = [self.get_data()]
  File "C:\Users\onebean5\anaconda3\envs\marllib\lib\site-packages\ray\rllib\evaluation\sampler.py", line 233, in get_data
    item = next(self._env_runner)
  File "C:\Users\onebean5\anaconda3\envs\marllib\lib\site-packages\ray\rllib\evaluation\sampler.py", line 591, in _env_runner
    summarize(unfiltered_obs)))
  File "C:\Users\onebean5\anaconda3\envs\marllib\lib\site-packages\ray\rllib\utils\debug.py", line 20, in summarize
    return _printer.pformat(_summarize(obj))
  File "C:\Users\onebean5\anaconda3\envs\marllib\lib\site-packages\ray\rllib\utils\debug.py", line 25, in _summarize
    return {k: _summarize(v) for k, v in obj.items()}
  File "C:\Users\onebean5\anaconda3\envs\marllib\lib\site-packages\ray\rllib\utils\debug.py", line 25, in <dictcomp>
    return {k: _summarize(v) for k, v in obj.items()}
  File "C:\Users\onebean5\anaconda3\envs\marllib\lib\site-packages\ray\rllib\utils\debug.py", line 25, in _summarize
    return {k: _summarize(v) for k, v in obj.items()}
  File "C:\Users\onebean5\anaconda3\envs\marllib\lib\site-packages\ray\rllib\utils\debug.py", line 25, in <dictcomp>
    return {k: _summarize(v) for k, v in obj.items()}
  File "C:\Users\onebean5\anaconda3\envs\marllib\lib\site-packages\ray\rllib\utils\debug.py", line 25, in _summarize
    return {k: _summarize(v) for k, v in obj.items()}
  File "C:\Users\onebean5\anaconda3\envs\marllib\lib\site-packages\ray\rllib\utils\debug.py", line 25, in <dictcomp>
    return {k: _summarize(v) for k, v in obj.items()}
  File "C:\Users\onebean5\anaconda3\envs\marllib\lib\site-packages\ray\rllib\utils\debug.py", line 39, in _summarize
    elif obj.dtype == np.object or obj.dtype.type is np.str_:
  File "C:\Users\onebean5\anaconda3\envs\marllib\lib\site-packages\numpy\__init__.py", line 305, in __getattr__
    raise AttributeError(__former_attrs__[attr])
AttributeError: module 'numpy' has no attribute 'object'.
`np.object` was a deprecated alias for the builtin `object`. To avoid this error in existing code, use `object` by itself. Doing this will not modify any behavior and is safe. 
The aliases was originally deprecated in NumPy 1.20; for more details and guidance see the original release note at:
    https://numpy.org/devdocs/release/1.20.0-notes.html#deprecations

